Workbook

Sheet CHECKS
A1: FERRAGAMO VALUATION MODEL — DATA INTEGRITY CHECKS
A2: Prepared by: ARYAN Shrenick Kothari | B2: Company: Salvatore Ferragamo S.p.A. | C2: Date: November 2025
A4: CHECK | B4: DESCRIPTION | C4: 2022A | D4: 2023A | E4: 2024A | F4: Year +1 | G4: Year +2 | H4: Year +3 | I4: Year +4 | J4: Year +5 | K4: PASS/FAIL | L4: TOLERANCE | M4: NOTE
A5: BS-1 | B5: Balance Sheet: Assets = Liabilities + Equity (EUR 000s) | C5: ='Forecasts '!B239 -> 0 | D5: ='Forecasts '!C239 -> 0 | E5: ='Forecasts '!D239 -> 0 | F5: ='Forecasts '!E239 -> 0 | G5: ='Forecasts '!F239 -> 0 | H5: ='Forecasts '!G239 -> 0 | I5: ='Forecasts '!H239 -> 0 | J5: ='Forecasts '!I239 -> 0 | K5: =IF(AND(ABS(C5)<1,ABS(D5)<1,ABS(E5)<1,ABS(F5)<1,ABS(G5)<1,ABS(H5)<1,ABS(I5)<1,ABS(J5)<1),"✓ PASS","✗ FAIL") -> ✓ PASS | L5: < 1 (rounding) | M5: A = L + E check (FSAP check row 239 in Forecasts)
A6: CF-1 | B6: Cash Flow: Net Change in Cash = Change in Cash Balance | C6: N/A | D6: ='Forecasts '!C310 -> 0 | E6: ='Forecasts '!D310 -> 0 | F6: ='Forecasts '!E310 -> 1.5279511e-10 | G6: ='Forecasts '!F310 -> -2.1827873e-11 | H6: ='Forecasts '!G310 -> -2.9831426e-10 | I6: ='Forecasts '!H310 -> -1.3460522e-10 | J6: ='Forecasts '!I310 -> 3.783498e-10 | K6: =IF(AND(ABS(D6)<0.001,ABS(E6)<0.001,ABS(F6)<0.001,ABS(G6)<0.001,ABS(H6)<0.001,ABS(I6)<0.001,ABS(J6)<0.001),"✓ PASS","✗ FAIL") -> ✓ PASS | L6: < 0.001 | M6: Net change in cash ties to balance sheet movement (row 310)
A7: IS-1 | B7: Net Income: IS Net Income = Cash Flow Net Income | C7: N/A (CFS starts 2023) | D7: ='Forecasts '!C77-'Forecasts '!C273 -> 0 | E7: ='Forecasts '!D77-'Forecasts '!D273 -> 0 | F7: ='Forecasts '!E77-'Forecasts '!E273 -> 0 | G7: ='Forecasts '!F77-'Forecasts '!F273 -> 0 | H7: ='Forecasts '!G77-'Forecasts '!G273 -> 0 | I7: ='Forecasts '!H77-'Forecasts '!H273 -> 0 | J7: ='Forecasts '!I77-'Forecasts '!I273 -> 0 | K7: =IF(AND(ABS(D7)<1,ABS(E7)<1,ABS(F7)<1,ABS(G7)<1,ABS(H7)<1,ABS(I7)<1,ABS(J7)<1),"✓ PASS","✗ FAIL") -> ✓ PASS | L7: < 1 (rounding) | M7: Net income per IS (row 77) = Net income per CFS (row 273)
A8: VAL-1 | B8: Valuation: All 3 equity models within 2% of each other | C8: N/A | D8: N/A | E8: N/A | F8: =ABS('Valuation '!F4-'Valuation '!F5) -> 0.0030599022 | G8: =ABS('Valuation '!F4-'Valuation '!F6) -> 0.0030599022 | H8: =ABS('Valuation '!F5-'Valuation '!F6) -> 1.3322676e-15 | I8: N/A | J8: N/A | K8: =IF(AND(ABS(F8)<0.1,ABS(G8)<0.1,ABS(H8)<0.1),"✓ PASS","✗ FAIL") -> ✓ PASS | L8: < 0.10 per share | M8: Dividend, FCF, and Residual Income per-share values should converge
A9: WACC-1 | B9: WACC: LT Growth Rate < WACC (Gordon Growth Model stability condition) | C9: N/A | D9: N/A | E9: N/A | F9: ='Valuation '!F53-'Valuation '!F23 -> 0.035455951 | G9: N/A | H9: N/A | I9: N/A | J9: N/A | K9: =IF('Valuation '!F53>'Valuation '!F23,"✓ PASS","✗ FAIL") -> ✓ PASS | L9: WACC > g | M9: WACC must exceed LT growth rate for Gordon Growth stability

Sheet AUDIT_LOG
A1: Sheet | B1: Cell | C1: Line Item | D1: Original Value / Issue | E1: Expected Logic / Correct Value | F1: Self-Question / Check | G1: Verdict | H1: Fix Applied | I1: Source | J1: Status
A2: EXEC SUMMARY | B2: E5 | C2: EBITDA 2024A | D2: 18939 | E2: 215,218 — prior figure omitted D&A (264,219) from EBIT (-49,001). EBITDA = EBIT + D&A. | F2: Was EBITDA computed as Revenue × margin or EBIT + D&A? | G2: ERROR | H2: Corrected: EBITDA = -49,001 + 264,219 = 215,218. Formula updated in EXEC SUMMARY. | I2: Forecasts sheet row 30 (D&A); FSAP Income Statement | J2: FIXED
A3: EXEC SUMMARY | B3: E28 | C3: ROIC 2024A | D3: 0.0538 | E3: -5.16% — ROIC cannot be positive when EBIT is negative (-49,001). Prior figure used incorrect NOPAT. | F3: Is NOPAT = EBIT×(1-t) positive when EBIT is negative? | G3: ERROR | H3: Corrected: ROIC = EBIT×(1-t) / Avg. Invested Capital = -49,001×0.845 / 800,000 ≈ -5.16%. | I3: Forecasts sheet; Company 2024A Annual Report | J3: FIXED
A4: EXEC SUMMARY | B4: F38 | C4: WACC | D4: 0.0652 | E4: 6.62% — used effective tax rate 15.5% (not statutory 21%). After-tax cost of debt = 6.0%×(1-0.155) = 5.07%. | F4: Which tax rate applies for WACC: statutory or effective? | G4: ERROR | H4: Corrected: WACC = 7.27%×0.703 + 5.07%×0.297 = 6.62%. Updated in Valuation sheet. | I4: Valuation sheet; FSAP WACC parameters | J4: FIXED
A5: EXEC SUMMARY | B5: F39 | C5: Economic Spread (ROIC-WACC) | D5: -0.0114 | E5: -11.68% — computed as corrected ROIC (-5.16%) minus WACC (6.62%) = -11.78%. | F5: Was economic spread computed using corrected ROIC and WACC? | G5: ERROR | H5: Corrected: Spread = -5.16% - 6.62% = -11.78%. ROIC < WACC confirms value destruction. | I5: Derived from corrected ROIC and WACC above | J5: FIXED
A6: OUTPUT SHEET | B6: D12/D13 | C6: P/E and EV/EBITDA 2024A | D6: Formulas dividing by wrong unit (000s vs €) | E6: P/E: Market Cap / Net Income; EV/EBITDA: EV / EBITDA. Units must be consistent (all EUR 000s). | F6: Are market cap and earnings in the same denomination? | G6: ERROR | H6: Noted on Output Sheet. 2024A P/E is negative (-20.3x) due to net loss; EV/EBITDA 2024A = 7.8x using corrected EBITDA. | I6: EXEC SUMMARY comp table; Output Sheet formulas | J6: FLAGGED
A7: EXEC SUMMARY | B7: Comp Table | C7: Peer Set Inconsistency | D7: COMP Sheet shows different peer set vs EXEC SUMMARY table | E7: Peers on EXEC SUMMARY (LVMH, Kering, Burberry, Moncler) partially differ from COMP Sheet. Both should show identical multiples. | F7: Are COMP Sheet and EXEC SUMMARY sourced from same data? | G7: WARNING | H7: Flagged for analyst review. EXEC SUMMARY peer table uses manually entered consensus multiples; COMP Sheet may reflect different data vintage. | I7: COMP Sheet; EXEC SUMMARY section | J7: FLAGGED — ANALYST TO RECONCILE
A8: Forecast Development | B8: E103/Row~103 | C8: IFRS 16 Lease D&A — Historical Actuals | D8: 2022A and 2023A show zero for IFRS 16 lease D&A | E8: IFRS 16 adopted by Ferragamo from FY2019. FY2022 and FY2023 should contain non-zero lease depreciation. Only FY2024A value of 232,865 entered. | F8: Was IFRS 16 in effect in FY2022 and FY2023? | G8: WARNING | H8: Flagged: historical IFRS 16 D&A values for FY2022 (est. ~220,000) and FY2023 (est. ~232,000) not populated. Analyst to confirm from Annual Reports pages 120-125. | I8: Ferragamo 2023 Annual Report — Notes to Financial Statements | J8: NEEDS DATA — ANALYST TO COMPLETE
A9: Forecast Development | B9: Depreciation table | C9: Implied Useful Life of PP&E | D9: 1.55 years (shown in historical computation) | E9: 10 years assumed in Useful Life Forecast. Historical implied life of ~1.55 years is nonsensical — caused by IFRS 16 D&A in denominator without corresponding PP&E in numerator. | F9: Does the depreciation base (PP&E at cost) include IFRS 16 right-of-use assets? | G9: DATA ISSUE | H9: Useful Life for forecast set to 10 years (analyst override). Historical ratio is misleading — IFRS 16 D&A inflated denominator. Recommend disclosing note. | I9: Forecast Development depreciation schedule; IFRS 16 note | J9: OVERRIDE APPLIED — 10 YR LIFE USED
A10: Forecasts | B10: E30 | C10: D&A Forecast — IFRS 16 Fix | D10: Prior formula only included capex-schedule D&A (~43,793 in Y+1) | E10: Corrected formula includes BOTH capex-schedule D&A (95% of Forecast Dev E80) AND IFRS 16 lease D&A (Forecast Dev E85). Year +1 D&A = 43,792 + 228,208 = 271,999. | F10: Was IFRS 16 lease depreciation included in the D&A line? | G10: ERROR | H10: Fixed: =-(Forecast Dev E80×0.95 + Forecast Dev E85). Applied to all forecast years E30:I30. | I10: Forecast Development row 85 (IFRS 16 D&A); IS row 30 | J10: FIXED
A11: Valuation | B11: All models | C11: Negative Per-Share Values (-€2.46) | D11: All FSAP valuation models return -€2.46/share | E11: Negative equity value is mathematically correct given deeply negative net income forecasts in Years +1 to +5. The FSAP model mechanically discounts negative cash flows. | F11: Is negative valuation a model error or a legitimate forecast outcome? | G11: MODEL OUTCOME | H11: Confirmed legitimate model output — not an error. The blended target price of €7.02 on EXEC SUMMARY uses an analyst overlay (FCF-based, P/E-based, EV/EBITDA-based) that adjusts for the transition period and normalised earnings. Both outputs disclosed. | I11: EXEC SUMMARY blended valuation; FSAP Valuation sheet | J11: DISCLOSED — ANALYST OVERLAY APPLIED
A12: EXEC SUMMARY | B12: Row 2 | C12: Target Price | D12: EUR 7.02 | E12: Blended valuation: 50% FCFF (€7.02×0.5=€3.51) + 25% P/E (€9.75×0.25=€2.44) + 25% EV/EBITDA (€8.40×0.25=€2.10) = €8.05. Note: Rating header shows €7.02 but blended formula gives €8.05. | F12: Does the target price on the header match the blended formula output? | G12: DISCREPANCY | H12: Flagged: header says €7.02 but blended calculation = €8.05. Recommend updating header to €8.05 or documenting the difference. | I12: EXEC SUMMARY valuation table row | J12: FLAGGED — ANALYST TO CONFIRM TARGET PRICE
A13: Forecasts | B13: E83/F83... | C13: Depreciation — Portion in COGS vs. IS | D13: Depreciation split: 95% to IS D&A line; 5% to COGS | E13: Standard FSAP split. Ferragamo reports some manufacturing D&A within cost of production. The 5%/95% split is an estimate; analyst should verify against segment note. | F13: Is the 5% COGS / 95% IS D&A split supportable from the annual report? | G13: ASSUMPTION | H13: Noted as assumption. Source: FSAP default methodology. Recommend verifying against Ferragamo 2024AR manufacturing cost disclosure. | I13: Forecast Development rows 82-83; FSAP methodology | J13: ASSUMPTION — VERIFY FROM AR

Sheet EXEC SUMMARY
A1: SALVATORE FERRAGAMO S.P.A. (SFER:IM) | Executive Summary | One-Page Model Output
A2: Rating: HOLD / NEUTRAL | Current Price: EUR 6.82 | Target Price: EUR 8.05 (Blended) | Implied Upside: +18.0% | Date: March 2026 | *FY2025E revised post H1 2025 actuals (Revenue €474M, Net loss -€57.5M)
A4: INCOME STATEMENT (EUR 000s) | B4: 2024A | C4: 2025E | D4: 2026E | F4: VALUATION SUMMARY (EUR PER SHARE) | G4: Bear | H4: Base | I4: Bull | L4: Wt. | M4: Wtd.
A5: Revenue | B5: 1035106 | C5: ='Forecasts '!E14 -> 1046253.4 | D5: ='Forecasts '!F14 -> 1083489.9 | F5: FCF-Based (FCFF) | G5: 3.45 | H5: 7.02 | I5: 11.8 | L5: 0.5 | M5: 3.51
A6: Growth (%) | B6: -0.1048 | C6: 0.0107 | D6: 0.0355 | F6: P/E-Based (8.7x Model FWD / 21.7x Consensus NTM) | G6: 5.1 | H6: 9.75 | I6: 14.6 | L6: 0.25 | M6: 2.44
A7: Gross Profit | B7: 740008 | C7: 748071 | D7: 774695 | F7: EV/EBITDA (8.1x implied) | G7: 4.3 | H7: 8.4 | I7: 12.8 | L7: 0.25 | M7: 2.1
A8: Gross Margin (%) | B8: 0.7149 | C8: 0.715 | D8: 0.715 | F8: Blended Intrinsic Value | H8: 8.05 | M8: 8.05
A9: EBITDA | B9: 215218 | C9: ='Forecasts '!E48-'Forecasts '!E30 -> 249008.32 | D9: ='Forecasts '!F48-'Forecasts '!F30 -> 257870.59 | F9: Current Market Price | H9: 6.82
A10: EBITDA Margin (%) | B10: 0.2079 | C10: =C9/'Forecasts '!E14 -> 0.238 | D10: =D9/'Forecasts '!F14 -> 0.238 | F10: Implied Upside/(Downside) | H10: 0.18
A11: EBIT | B11: -49001 | C11: ='Forecasts '!E48 -> -22991.489 | D11: ='Forecasts '!F48 -> -13476.504
A12: Net Income | B12: -68069 | C12: ='Forecasts '!E90 -> -38957.235 | D12: ='Forecasts '!F90 -> -31223.901 | F12: COMPARABLE COMPANY MULTIPLES
A13: EPS (EUR) | B13: -0.403 | C13: ='Forecasts '!E90/'Valuation '!F19 -> -0.23080298 | D13: ='Forecasts '!F90/'Valuation '!F19 -> -0.18498668 | F13: Company | G13: EV/EBITDA | H13: Fwd P/E | I13: P/B | K13: FCF Yield | L13: Div Yld
A14: Net Margin (%) | B14: -0.0658 | C14: ='Forecasts '!E90/'Forecasts '!E14 -> -0.037234988 | D14: ='Forecasts '!F90/'Forecasts '!F14 -> -0.028817899 | F14: Salvatore Ferragamo (SFER) | G14: 8.1x | H14: 21.7x | I14: 2.15x | K14: 0.102 | L14: 0.012
A15: BALANCE SHEET HIGHLIGHTS (EUR 000s) | B15: 2024A | C15: 2025E | D15: 2026E | F15: LVMH | G15: 11.2x | H15: 18.5x | I15: 2.90x | K15: 0.058 | L15: 0.019
A16: Total Assets | B16: 1744841 | C16: 1775000 | D16: 1810000 | F16: Kering | G16: 9.6x | H16: 22.4x | I16: 2.10x | K16: 0.063 | L16: 0.034
A17: Cash | B17: 238194 | C17: 257094 | D17: 270340 | F17: Burberry | G17: 7.8x | H17: 19.1x | I17: 1.75x | K17: 0.072 | L17: 0.028
A18: Net PPE | B18: 207000 | C18: 228208 | D18: 246574 | F18: Moncler | G18: 13.4x | H18: 24.3x | I18: 4.50x | K18: 0.049 | L18: 0.012
A19: Gross Financial Debt | B19: 567067 | C19: 560000 | D19: 550000 | F19: Peer Average | G19: 9.8x | H19: 21.0x | I19: 2.51x | K19: 0.065 | L19: 0.023
A20: Net Debt | B20: 328873 | C20: 302906 | D20: 279660
A21: Total Equity | B21: 622445 | C21: 744323 | D21: 871428 | F21: INVESTMENT CONSIDERATIONS
A22: Net D/Equity (x) | B22: 0.528 | C22: 0.407 | D22: 0.321 | F22: BULL CASE CATALYSTS
A23: Total Equity | B23: 622445 | C23: 744323 | D23: 871428 | F23: • FY2025 results (6 Mar 2026) confirm revenue stabilisation / H2 beat
A24: CASH FLOW & FCF (EUR 000s) | B24: 2024A | C24: 2025E | D24: 2026E | F24: • China/APAC recovery confirmed in H2 2025 vs -18.5% H1 2025 decline
A25: CF from Operations | B25: 171204 | C25: 180000 | D25: 195000 | F25: • New brand campaigns ('L’appuntamento') drive DTC traffic/conversion above expectations
A26: Capex | B26: 61308 | C26: 65000 | D26: 68000 | F26: • Impairment charges normalise; DTC margin improvement confirms operating leverage
A27: FCFF | B27: 160896 | C27: 137249 | D27: 145395
A28: FCFE | B28: 109896 | C28: 117098 | D28: 127703 | F28: BEAR CASE RISKS
A29: FCFF Yield (%) | B29: 0.0942 | C29: 0.1024 | D29: 0.1085 | F29: • H1 2025 net loss -€57.5M; FY2025E ~-€95M loss; recovery delayed
A30: FCFF | B30: 160896 | C30: 137249 | D30: 145395 | F30: • ROIC -5.2% vs WACC 6.62% = -11.8% spread; deeply value-destructive
A31: RETURN RATIOS (%) | B31: 2024A | C31: 2025E | D31: 2026E | F31: • Asia Pacific -18.5% H1 2025; wholesale -17.9%; no near-term recovery catalyst
A32: ROA | B32: -0.0093 | C32: -0.093 | D32: 0.089 | F32: • Morgan Stanley PT €5.50 Underweight; JPMorgan PT €4.60; 14-analyst avg €6.79
A33: ROE | B33: -0.1011 | C33: -0.152 | D33: 0.1817
A34: ROIC | B34: -0.0516 | C34: -0.052 | D34: 0.093 | F34: WACC COMPONENTS
A35: WACC | B35: 0.0662 | C35: 0.0662 | D35: 0.0662 | F35: Risk-Free Rate (Rf, 10Y BTP) | G35: 0.0315
A36: Economic Spread | B36: -0.1168 | C36: -0.118 | D36: 0.0278 | F36: Equity Risk Premium | G36: 0.05
A37: Return on Assets (ROA) | B37: -0.0093 | C37: -0.093 | D37: 0.089 | F37: Beta (levered, 5Y monthly) | G37: 0.82x
A38: Return on Equity (ROE) | B38: -0.1011 | C38: -0.152 | D38: 0.1817 | F38: Cost of Equity (CAPM) | G38: 0.0727
A39: Return on Invested Capital | B39: -0.0516 | C39: -0.052 | D39: 0.093 | F39: Cost of Debt (pre-tax) | G39: 0.06
A40: WACC | B40: 0.0662 | C40: 0.0662 | D40: 0.0652 | F40: After-tax Cost of Debt | G40: 0.0474
A41: Economic Spread (ROIC-WACC) | B41: -0.1168 | C41: -0.118 | D41: 0.0278 | F41: Weight of Equity | G41: 0.703
...

Sheet Sheet1
R7: Factor | S7: 2024 (Actuals) | T7: 2025E (Year +1) | U7: 2026E (Year +2) | V7: Interpretation
R8: Total Debt/Total Assets | S8: 0.64 | T8: 0.7 | U8: 0.774 | V8: Increasing leverage as the proportion of assets financed by debt rises sharply in the forecast.
R9: NET DEBT/Total Equity | S9: 1.8 | T9: 2.338 | U9: 3.43 | V9: Very high and rapidly increasing reliance on debt relative to equity, indicating a highly leveraged structure.
R10: TIE (Interest Coverage Ratio) | S10: -0.17 | T10: 2.5 | U10: 2.2 | V10: Negative coverage in 2024, meaning operating profit wasn't enough to cover interest expense. Improvement is forecasted, but remains low.
R11: OCF/Total Liabilities | S11: 0.15 | T11: 0.197 | U11: 0.202 | V11: The ability to cover total liabilities with operating cash flow is moderate and improving, offering some resilience.
R12: FCF/Total Liabilities | S12: 0.14 | T12: 0.156 | U12: 0.18 | V12: The ability to cover total liabilities with free cash flow is moderate and improving.
B18: Row Name in your Excel | C18: 2023 Input (in thousands) | D18: 2024 Input (in thousands) | E18: Logic/Mapping for Final Fit
B19: Provisions for risks and charges | C19: 23928 | D19: 22514 | E19: Direct from report
B20: Employee benefit liabilities | C20: 6954 | D20: 6026 | E20: Direct from report
B21: Other non-current liabilities | C21: 16223 | D21: 14723 | E21: Other non-current liabilities (Note 25)
B22: Non-current lease liabilities | C22: 596603 | D22: 552344 | E22: Direct from report
B23: Deferred tax liabilities | C23: 0 | D23: 0 | E23: Assumed to be zero based on template pattern (DTL is in the lower block).
B24: Other current liabilities (1) | C24: 114439 | D24: 124002 | E24: Current lease liabilities
B25: Other current liabilities (2) | C25: 48806 | D25: 44151 | E25: Other current liabilities (Note 30)
B26: Other current liabilities (3) | C26: 296984 | D26: 311318 | E26: Combined: Trade Payables (1,73,323 / 1,64,446) + Combined Current Liabilities (1,23,661 / 1,46,872)
B27: Current Liabilities | C27: 0 | D27: 0 | E27: Assumed to be zero (calculated total).
B28: Long-term debt | C28: 0 | D28: 0 | E28: Assumed Zero.
B29: Long-term accrued liabilities | C29: 6589 | D29: 3404 | E29: Employee benefit liabilities (Long-term portion moved from row 2 based on template pattern)
B30: Deferred tax liabilities- noncurrent | C30: 6832 | D30: 5682 | E30: Deferred tax liabilities (Note 39)
... B33: Total Liabilities | C33: 1090769 | D33: 1080760 | E33: Matches Consolidated Report Total.
B35: Row Name in your Excel | C35: 2023 Input (in thousands) | D35: 2024 Input (in thousands) | E35: Source/Logic from Consolidated Report
B36: Preferred stock | C36: 0 | D36: 0 | E36: Not reported.
B37: Common stock + Additional paid in capital | C37: 695106 | D37: 687178 | E37: Share capital + Reserves (Group)
B38: Retained earnings <deficit> | C38: 26060 | D38: -68087 | E38: Net profit/(loss) – Group
B39: Accum. other comprehensive income <loss> | C39: 3934 | D39: 3354 | E39: Plug figure (based on template pattern) to help balance total equity.
B40: <Treasury stock> and other equity adjustments | C40: 0 | D40: 0 | E40: Not reported. | Q40: Template Row Name | R40: 2022 Report Line | S40: Current 2022 Value (Template) | T40: CORRECT 2022 VALUE | U40: 2023 Report Line | V40: CORRECT 2023 VALUE
B41: Noncontrolling interests | C41: 997 | D41: 995 | E41: Total Minority Interests | Q41: <Operating Expenses (1)> | R41: Sales & distribution costs | S41: -482315 | T41: -453167 | U41: Sales & distribution costs | V41: -454649
B42: Total Equity | C42: 722163 | D42: 620086 | E42: TOTAL SHAREHOLDERS’ EQUITY | Q42: <Operating Expenses (2)> | R42: General and administrative costs | S42: -127837 | T42: -168819 | U42: General and administrative costs | V42: -137142
B44: Total Liabilities and Equities | C44: 1812932 | D44: 1700846 | E44: Must match TOTAL ASSETS | Q44: <Selling, General and Administrative Expenses> | R44: Style, product development and logistics costs | S44: -50292 | T44: -49263 | U44: Style, product development and logistics costs | V44: -53086
Q45: Other operating expenses (1) | R45: Marketing & communication costs | S45: -79676 | T45: -92064 | U45: Communication and marketing costs | V45: -113695
B46: Row Name in your Excel | C46: 2023 Input (in thousands) | D46: 2024 Input (in thousands) | E46: Logic/Mapping from Consolidated Report | Q46: Other operating expenses (2) | R46: Other operating costs | S46: -24467 | T46: -29024 | U46: Other operating costs | V46: -29721
B47: Cash and cash equivalents | C47: 268988 | D47: 238194 | E47: Direct from report
B48: Short-term investments | C48: 0 | D48: 0 | E48: Not reported as distinct item.
B49: Accounts and notes receivable - net | C49: 106821 | D49: 84580 | E49: Trade receivables
B50: Inventories | C50: 298345 | D50: 307888 | E50: Inventories
B51: Prepaid expenses and other current assets | C51: 37712 | D51: 46025 | E51: Other current assets
B52: Other current assets (1) | C52: 36812 | D52: 50721 | E52: Other current financial assets
B53: Other current assets (2) | C53: 34025 | D53: 25822 | E53: Tax receivables
B54: Other current assets (3) | C54: 6107 | D54: 5978 | E54: Sum of: Right of return assets (6,044/5,911) + Assets held for sale (63/67) | R54: Template Row Name | S54: Current 2022 Value | T54: CORRECT 2022 VALUE | U54: Current 2023 Value | V54: CORRECT 2023 VALUE | W54: Rationale (Official Annual Report Line)
B55: TOTAL CURRENT ASSETS | C55: 788810 | D55: 759288 | E55: Calculated total (Close to 788,747 / 759,141) | R55: <Operating Expenses (2)> | S55: $\text{-1,27,837}$ | T55: -168819 | U55: $\text{-1,37,142}$ | V55: -137142 | W55: General and administrative costs
...

Sheet Data 
A2: Analyst Name: | B2: ARYAN Shrenick kothari
A3: Company Name: | B3: Salvatore Ferragamo Group
A4: Year (Most recent in far right column.) | B4: 2019 | C4: 2020 | D4: 2021 | E4: 2022 | F4: 2023 | G4: 2024
A7: BALANCE SHEET DATA
A8: Assets:
A9: Cash and cash equivalents | B9: 222332 | C9: 327880 | D9: 511796 | E9: 391354 | F9: 268988 | G9: 238194
A10: Short-term investments
A11: Accounts and notes receivable - net | B11: 147202 | C11: 113909 | D11: 112670 | E11: 94490 | F11: 106821 | G11: 84580
A12: Inventories | B12: 389531 | C12: 341636 | D12: 274566 | E12: 275323 | F12: 298345 | G12: 307888
A13: Prepaid expenses and other current assets | B13: 32980 | C13: 35944 | D13: 32606 | E13: 41447 | F13: 37712 | G13: 46025
A14: Other current assets (1) | B14: 5473 | C14: 4545 | D14: 5224 | E14: 5703 | F14: 36812 | G14: 50721
A15: Other current assets (2) | B15: 20107 | C15: 15974 | D15: 27512 | E15: 30581 | F15: 34025 | G15: 25822
A16: Other current assets (3) | B16: 101 | C16: 566 | D16: 596 | E16: 10255 | F16: 6107 | G16: 5978
A17: Current Assets | B17: =SUM(B9:B16) -> 817726 | C17: =SUM(C9:C16) -> 840454 | D17: =SUM(D9:D16) -> 964970 | E17: =SUM(E9:E16) -> 849153 | F17: =SUM(F9:F16) -> 788810 | G17: =SUM(G9:G16) -> 759208
A18: Long-term investments | B18: 16939 | C18: 15574 | D18: 15659 | E18: 15570 | F18: 37764 | G18: 32361
A19: Equity and cost investments | B19: 39091 | C19: 31824 | D19: 30223 | E19: 27747 | F19: 28500 | G19: 22489
A20: Property, plant, and equipment - at cost | B20: 251805 | C20: 183121 | D20: 336315 | E20: 341750 | F20: 400000 | G20: 420000
A21: <Accumulated depreciation> | B21: 0 | C21: 0 | D21: -149461 | E21: -150186 | F21: -176646 | G21: -208000
A22: Deferred income taxes - noncurrent | B22: 96736 | C22: 119656 | D22: 105468 | E22: 109090 | F22: 122349 | G22: 145142
A23: Other assets | B23: 708399 | C23: 477661 | D23: 505779 | E23: 485584 | F23: 639278 | G23: 535090
A24: Other intangible assets | B24: 42484 | C24: 38891 | D24: 33423 | E24: 34903 | F24: 36872 | G24: 31872
A25: Goodwill | B25: - | C25: 6679 | D25: 6679 | E25: 6679 | F25: 6679 | G25: 6679
A26: Total Assets | B26: =SUM(B17:B25) -> 1973180 | C26: =SUM(C17:C25) -> 1713860 | D26: =SUM(D17:D25) -> 1849055 | E26: =SUM(E17:E25) -> 1720290 | F26: =SUM(F17:F25) -> 1883606 | G26: =SUM(G17:G25) -> 1744841
A28: Liabilities and Equities:
A29: Provisions for risks and charges | B29: 198934 | C29: 136399 | D29: 183792 | E29: 174016 | F29: 23928 | G29: 22514
A30: Employee benefit liabilities | B30: 8720 | C30: 9139 | D30: 9310 | E30: 10100 | F30: 6954 | G30: 6026
A31: Other non-current liabilities | B31: 48060 | C31: 56698 | D31: 75604 | E31: 29264 | F31: 16223 | G31: 14723
A32: Non-current lease liabilities | B32: 117062 | C32: 103509 | D32: 110012 | E32: 106586 | F32: 596603 | G32: 552344
A33: Deferred tax liabilities
A34: Other current liabilities (1) | B34: 26491 | C34: 25974 | D34: 25732 | E34: 25216 | F34: 114439 | G34: 124002
A35: Other current liabilities (2) | B35: 54317 | C35: 29362 | D35: 58929 | E35: 77835 | F35: 48806 | G35: 44151
A36: Other current liabilities (3) | B36: 2477 | C36: 3703 | D36: 513 | E36: 1096 | F36: 296984 | G36: 311318
A37: Current Liabilities | B37: =SUM(B29:B36) -> 456061 | C37: =SUM(C29:C36) -> 364784 | D37: =SUM(D29:D36) -> 463892 | E37: =SUM(E29:E36) -> 424113 | F37: =SUM(F29:F36) -> 1103937 | G37: =SUM(G29:G36) -> 1075078
A38: Long-term debt | B38: 129302 | C38: 129302 | D38: 63516 | E38: 0 | F38: 0 | G38: 0
A39: Long-term accrued liabilities | B39: 559267 | C39: 464400 | D39: 487230 | E39: 468737 | F39: 6589 | G39: 3404
A40: Deferred tax liabilities- noncurrent | B40: 5570 | C40: 6943 | D40: 3380 | E40: 6071 | F40: 6832 | G40: 5682
A41: Other noncurrent liabilities (1) | B41: 25814 | C41: 26868 | D41: 36188 | E41: 38379 | F41: 16223 | G41: 14723
A42: Other noncurrent liabilities (2) | B42: 11901 | C42: 11867 | D42: 8970 | E42: 7581 | F42: 23928 | G42: 22514
A43: Total Liabilities | B43: =SUM(B37:B42) -> 1187915 | C43: =SUM(C37:C42) -> 1004164 | D43: =SUM(D37:D42) -> 1063176 | E43: =SUM(E37:E42) -> 944881 | F43: =SUM(F37:F42) -> 1157509 | G43: =SUM(G37:G42) -> 1121401
A45: Preferred stock
...

Sheet Forecast Development 
A2: Analyst Name: | B2: ='Data '!B2 -> ARYAN Shrenick kothari
A3: Company Name: | B3: ='Data '!B3 -> Salvatore Ferragamo Group
A7: Revenue Forecast Development
B9: Actuals | E9: Forecasts
A10: Year | B10: ='Forecasts '!B12 -> 2022 | C10: ='Forecasts '!C12 -> 2023 | D10: ='Forecasts '!D12 -> 2024 | E10: ='Forecasts '!E12 -> Year +1 | F10: ='Forecasts '!F12 -> Year +2 | G10: ='Forecasts '!G12 -> Year +3 | H10: ='Forecasts '!H12 -> Year +4 | I10: ='Forecasts '!I12 -> Year +5
A12: Net Revenues (in millions):
A13: Europe | B13: 262900 | C13: 243200 | D13: 252400 | E13: =E23 -> 257448 | F13: =F23 -> 265171.44 | G13: =G23 -> 273656.93 | H13: =H23 -> 282413.95 | I13: =I23 -> 292580.85
A14: Americas | B14: 414700 | C14: 379600 | D14: 397900 | E14: =E27 -> 407847.5 | F14: =F27 -> 422122.16 | G14: =G27 -> 438162.8 | H14: =H27 -> 456565.64 | I14: =I27 -> 476654.53
A15: Asia | B15: 574208 | C15: 533471 | D15: 384806 | E15: =E31 -> 380957.94 | F15: =F31 -> 396196.26 | G15: =G31 -> 419968.03 | H15: =H31 -> 445166.12 | I15: =I31 -> 463863.09
A16: Total Net Revenues | B16: =SUM(B13:B15) -> 1251808 | C16: =SUM(C13:C15) -> 1156271 | D16: =SUM(D13:D15) -> 1035106 | E16: =SUM(E13:E15) -> 1046253.4 | F16: =SUM(F13:F15) -> 1083489.9 | G16: =SUM(G13:G15) -> 1131787.8 | H16: =SUM(H13:H15) -> 1184145.7 | I16: =SUM(I13:I15) -> 1233098.5
A17: rates of change | C17: =C16/B16-1 -> -0.076319212 | D17: =D16/C16-1 -> -0.10478945 | E17: =E16/D16-1 -> 0.01076937 | F17: =F16/E16-1 -> 0.035590249 | G17: =G16/F16-1 -> 0.04457624 | H17: =H16/G16-1 -> 0.046261272 | I17: =I16/H16-1 -> 0.041340155
E18: Implied revenue growth rates.
A20: Summary: Revenues by Segment and Type: | E20: Revenue Forecasts by Segment and Type
B21: =B10 -> 2022 | C21: =C10 -> 2023 | D21: =D10 -> 2024 | E21: =E10 -> Year +1 | F21: =F10 -> Year +2 | G21: =G10 -> Year +3 | H21: =H10 -> Year +4 | I21: =I10 -> Year +5
A23: =A13 -> Europe | B23: =B13 -> 262900 | C23: =C13 -> 243200 | D23: =D13 -> 252400 | E23: =D23*(1+E24) -> 257448 | F23: =E23*(1+F24) -> 265171.44 | G23: =F23*(1+G24) -> 273656.93 | H23: =G23*(1+H24) -> 282413.95 | I23: =H23*(1+I24) -> 292580.85
A24: Growth rates | C24: =C23/B23-1 -> -0.074933435 | D24: =D23/C23-1 -> 0.037828947 | E24: 0.02 | F24: 0.03 | G24: 0.032 | H24: 0.032 | I24: 0.036
C25: =AVERAGE(C24:D24) -> -0.018552244
A27: =A14 -> Americas | B27: =B14 -> 414700 | C27: =C14 -> 379600 | D27: =D14 -> 397900 | E27: =D27*(1+E28) -> 407847.5 | F27: =E27*(1+F28) -> 422122.16 | G27: =F27*(1+G28) -> 438162.8 | H27: =G27*(1+H28) -> 456565.64 | I27: =H27*(1+I28) -> 476654.53
A28: Growth rates | C28: =C27/B27-1 -> -0.084639498 | D28: =D27/C27-1 -> 0.048208641 | E28: 0.025 | F28: 0.035 | G28: 0.038 | H28: 0.042 | I28: 0.044
C29: =AVERAGE(C28:D28) -> -0.018215429
A31: =A15 -> Asia | B31: =B15 -> 574208 | C31: =C15 -> 533471 | D31: =D15 -> 384806 | E31: =D31*(1+E32) -> 380957.94 | F31: =E31*(1+F32) -> 396196.26 | G31: =F31*(1+G32) -> 419968.03 | H31: =G31*(1+H32) -> 445166.12 | I31: =H31*(1+I32) -> 463863.09
A32: Growth rates | C32: =C31/B31-1 -> -0.070944675 | D32: =D31/C31-1 -> -0.27867494 | E32: -0.01 | F32: 0.04 | G32: 0.06 | H32: 0.06 | I32: 0.042
C33: =AVERAGE(C32:D32) -> -0.17480981
A35: Revenues | B35: =B23+B27+B31 -> 1251808 | C35: =C23+C27+C31 -> 1156271 | D35: =D23+D27+D31 -> 1035106 | E35: =E23+E27+E31 -> 1046253.4 | F35: =F23+F27+F31 -> 1083489.9 | G35: =G23+G27+G31 -> 1131787.8 | H35: =H23+H27+H31 -> 1184145.7 | I35: =I23+I27+I31 -> 1233098.5
A41: Forecast Development: Capital Expenditures, Property, Plant and Equipment, and Depreciation
A43: Capital Expenditures: | E43: 41000 | K43: The Capital Expenditures schedule permits the FSAP user to build detailed forecasts of future capital expenditures as a percent of future revenues, gross PP&E or any other reasonable basis for these forecast assumptions.
B44: =B10 -> 2022 | C44: =C10 -> 2023 | D44: =D10 -> 2024 | E44: =E10 -> Year +1 | F44: =F10 -> Year +2 | G44: =G10 -> Year +3 | H44: =H10 -> Year +4 | I44: =I10 -> Year +5
A45: CAPEX:
A46: PP&E Acquired | B46: =-'Data '!E108 -> 41608 | C46: =-'Data '!F108 -> 58086 | D46: =-'Data '!G108 -> 61308 | E46: 41000 | F46: =E46*1.005 -> 41205 | G46: =F46*1.005 -> 41411.025 | H46: =G46*1.005 -> 41618.08 | I46: =H46*1.01 -> 42034.261
A47: PP&E Sold | B47: =-'Data '!E107 -> 0 | C47: =-'Data '!F107 -> -53 | D47: =-'Data '!G107 -> -29 | E47: =D47*(1.05) -> -30.45 | F47: =E47*(1.05) -> -31.9725 | G47: =F47*(1.05) -> -33.571125 | H47: =G47*(1.05) -> -35.249681 | I47: =H47*(1.05) -> -37.012165
A48: Net CAPEX | B48: =B46+B47 -> 41608 | C48: =C46+C47 -> 58033 | D48: =D46+D47 -> 61279 | E48: =SUM(E46:E47) -> 40969.55 | F48: =SUM(F46:F47) -> 41173.027 | G48: =SUM(G46:G47) -> 41377.454 | H48: =SUM(H46:H47) -> 41582.83 | I48: =SUM(I46:I47) -> 41997.249
A50: Net CAPEX as a percent of:
A51: Gross PP&E | B51: =B48/'Data '!D20 -> 0.12371735 | C51: =C48/B60 -> 0.16981127 | D51: =D48/C60 -> 0.1531975 | E51: =E48/D60 -> 0.097546548 | F51: =F48/E60 -> 0.089318324 | G51: =G48/F60 -> 0.082401803 | H51: =H48/G60 -> 0.076506528 | I51: =I48/H60 -> 0.071777548
A52: Revenues | B52: =B48/'Data '!E58 -> 0.033238324 | C52: =C48/'Data '!F58 -> 0.050189791 | D52: =D48/'Data '!G58 -> 0.0592007 | E52: =E48/E16 -> 0.039158342 | F52: =F48/F16 -> 0.038000381 | G52: =G48/G16 -> 0.036559376 | H52: =H48/H16 -> 0.035116312 | I52: =I48/I16 -> 0.034058309
A55: Property, Plant and Equipment and Depreciation | E55: Property, Plant and Equipment and Depreciation Forecasts: | K55: The Property, Plant & Equipment and Depreciation schedule automatically computes for the FSAP detailed forecasts of future PP&E based on exisitng PP&E plus projected future capital expenditures. The Depreciation expense schedule automatically computes future depreciation expense based on exisitng depreciable PP&E future capital expenditures. The expected useful life for depreciation purposes is computed below.
K56: FSAP automatically links the projected amounts for gross PP&E, accumulated depreciation, depreciation expense, and capital expenditures into the financial statements in the Forecasts worksheet.
A57: PP&E at cost: | B57: =B44 -> 2022 | C57: =C44 -> 2023 | D57: =D44 -> 2024 | E57: =E44 -> Year +1 | F57: =F44 -> Year +2 | G57: =G44 -> Year +3 | H57: =H44 -> Year +4 | I57: =I44 -> Year +5
A58: Beg. balance at cost: | E58: =D60 -> 420000 | F58: =E60 -> 460969.55 | G58: =F60 -> 502142.58 | H58: =G60 -> 543520.03 | I58: =H60 -> 585102.86
A59: Add: CAPEX forecasts from above: | E59: =E48 -> 40969.55 | F59: =F48 -> 41173.027 | G59: =G48 -> 41377.454 | H59: =H48 -> 41582.83 | I59: =I48 -> 41997.249
A60: End balance at cost: | B60: ='Data '!E20 -> 341750 | C60: ='Data '!F20 -> 400000 | D60: ='Data '!G20 -> 420000 | E60: =E58+E59 -> 460969.55 | F60: =F58+F59 -> 502142.58 | G60: =G58+G59 -> 543520.03 | H60: =H58+H59 -> 585102.86 | I60: =I58+I59 -> 627100.11
...

Sheet Analysis 
A3: ='Data '!A2 -> Analyst Name: | B3: ='Data '!B2 -> ARYAN Shrenick kothari
A4: ='Data '!A3 -> Company Name: | B4: ='Data '!B3 -> Salvatore Ferragamo Group
A7: DATA CHECKS
A8: ='Data '!A147 -> Assets - Liabilities - Equities | B8: ='Data '!B147 -> 0 | C8: ='Data '!C147 -> 0 | D8: ='Data '!D147 -> 0 | E8: ='Data '!E147 -> 0 | F8: ='Data '!F147 -> 0
A9: ='Data '!A148 -> Net Income (computed) - Net Income (reported) | B9: ='Data '!B148 -> 0 | C9: ='Data '!C148 -> 0 | D9: ='Data '!D148 -> 0 | E9: ='Data '!E148 -> 0 | F9: ='Data '!F148 -> 0
A10: ='Data '!A149 -> Cash Changes | C10: ='Data '!C149 -> 0 | D10: ='Data '!D149 -> 0 | E10: ='Data '!E149 -> 0 | F10: ='Data '!F149 -> 0
A11: In the computations below, a #DIV/0! message indicates that a ratio denominator is zero.
A14: PROFITABILITY FACTORS:
A15: Year | B15: ='Data '!$C$4 -> 2020 | C15: ='Data '!$D$4 -> 2021 | D15: ='Data '!$E$4 -> 2022 | E15: ='Data '!$F$4 -> 2023 | F15: ='Data '!$G$4 -> 2024
A17: RETURN ON ASSETS (based on reported amounts):
A18: Profit Margin for ROA | B18: =IF(ISERROR(('Data '!C79+(1-'Data '!C135)*(-'Data '!C71))/'Data '!C58),"",('Data '!C79+(1-'Data '!C135)*(-'Data '!C71))/'Data '!C58) -> -0.0088102094 | C18: =IF(ISERROR(('Data '!D79+(1-'Data '!D135)*(-'Data '!D71))/'Data '!D58),"",('Data '!D79+(1-'Data '!D135)*(-'Data '!D71))/'Data '!D58) -> 0.10659703 | D18: =IF(ISERROR(('Data '!E79+(1-'Data '!E135)*(-'Data '!E71))/'Data '!E58),"",('Data '!E79+(1-'Data '!E135)*(-'Data '!E71))/'Data '!E58) -> 0.10187454 | E18: =IF(ISERROR(('Data '!F79+(1-'Data '!F135)*(-'Data '!F71))/'Data '!F58),"",('Data '!F79+(1-'Data '!F135)*(-'Data '!F71))/'Data '!F58) -> 0.070096656 | F18: =IF(ISERROR(('Data '!G79+(1-'Data '!G135)*(-'Data '!G71))/'Data '!G58),"",('Data '!G79+(1-'Data '!G135)*(-'Data '!G71))/'Data '!G58) -> -0.016348113
A19: x Asset Turnover | B19: =IF(ISERROR('Data '!C58/(('Data '!B26+'Data '!C26)/2)),"",'Data '!C58/(('Data '!B26+'Data '!C26)/2)) -> 0.49678062 | C19: =IF(ISERROR('Data '!D58/(('Data '!C26+'Data '!D26)/2)),"",'Data '!D58/(('Data '!C26+'Data '!D26)/2)) -> 0.63741066 | D19: =IF(ISERROR('Data '!E58/(('Data '!D26+'Data '!E26)/2)),"",'Data '!E58/(('Data '!D26+'Data '!E26)/2)) -> 0.70142169 | E19: =IF(ISERROR('Data '!F58/(('Data '!E26+'Data '!F26)/2)),"",'Data '!F58/(('Data '!E26+'Data '!F26)/2)) -> 0.64167834 | F19: =IF(ISERROR('Data '!G58/(('Data '!F26+'Data '!G26)/2)),"",'Data '!G58/(('Data '!F26+'Data '!G26)/2)) -> 0.57055043
A20: = Return on Assets | B20: =IF(ISERROR(('Data '!C79+(1-'Data '!C135)*(-'Data '!C71))/(('Data '!B26+'Data '!C26)/2)),"",('Data '!C79+(1-'Data '!C135)*(-'Data '!C71))/(('Data '!B26+'Data '!C26)/2)) -> -0.0043767412 | C20: =IF(ISERROR(('Data '!D79+(1-'Data '!D135)*(-'Data '!D71))/(('Data '!C26+'Data '!D26)/2)),"",('Data '!D79+(1-'Data '!D135)*(-'Data '!D71))/(('Data '!C26+'Data '!D26)/2)) -> 0.067946083 | D20: =IF(ISERROR(('Data '!E79+(1-'Data '!E135)*(-'Data '!E71))/(('Data '!D26+'Data '!E26)/2)),"",('Data '!E79+(1-'Data '!E135)*(-'Data '!E71))/(('Data '!D26+'Data '!E26)/2)) -> 0.071457015 | E20: =IF(ISERROR(('Data '!F79+(1-'Data '!F135)*(-'Data '!F71))/(('Data '!E26+'Data '!F26)/2)),"",('Data '!F79+(1-'Data '!F135)*(-'Data '!F71))/(('Data '!E26+'Data '!F26)/2)) -> 0.044979506 | F20: =IF(ISERROR(('Data '!G79+(1-'Data '!G135)*(-'Data '!G71))/(('Data '!F26+'Data '!G26)/2)),"",('Data '!G79+(1-'Data '!G135)*(-'Data '!G71))/(('Data '!F26+'Data '!G26)/2)) -> -0.009327423
A22: RETURN ON ASSETS (excluding the effects of nonrecurring items):
A23: Profit Margin for ROA | B23: =IF(ISERROR(('Data '!C79+((1-'Data '!C135)*-'Data '!C71)-'Data '!C137)/'Data '!C58),"",('Data '!C79+((1-'Data '!C135)*-'Data '!C71)-'Data '!C137)/'Data '!C58) -> 0.01783582 | C23: =IF(ISERROR(('Data '!D79+((1-'Data '!D135)*-'Data '!D71)-'Data '!D137)/'Data '!D58),"",('Data '!D79+((1-'Data '!D135)*-'Data '!D71)-'Data '!D137)/'Data '!D58) -> 0.13878516 | D23: =IF(ISERROR(('Data '!E79+((1-'Data '!E135)*-'Data '!E71)-'Data '!E137)/'Data '!E58),"",('Data '!E79+((1-'Data '!E135)*-'Data '!E71)-'Data '!E137)/'Data '!E58) -> 0.1294884 | E23: =IF(ISERROR(('Data '!F79+((1-'Data '!F135)*-'Data '!F71)-'Data '!F137)/'Data '!F58),"",('Data '!F79+((1-'Data '!F135)*-'Data '!F71)-'Data '!F137)/'Data '!F58) -> 0.13350868 | F23: =IF(ISERROR(('Data '!G79+((1-'Data '!G135)*-'Data '!G71)-'Data '!G137)/'Data '!G58),"",('Data '!G79+((1-'Data '!G135)*-'Data '!G71)-'Data '!G137)/'Data '!G58) -> 0.031471376
A24: x Asset Turnover | B24: =IF(ISERROR('Data '!C58/(('Data '!B26+'Data '!C26)/2)),"",'Data '!C58/(('Data '!B26+'Data '!C26)/2)) -> 0.49678062 | C24: =IF(ISERROR('Data '!D58/(('Data '!C26+'Data '!D26)/2)),"",'Data '!D58/(('Data '!C26+'Data '!D26)/2)) -> 0.63741066 | D24: =IF(ISERROR('Data '!E58/(('Data '!D26+'Data '!E26)/2)),"",'Data '!E58/(('Data '!D26+'Data '!E26)/2)) -> 0.70142169 | E24: =IF(ISERROR('Data '!F58/(('Data '!E26+'Data '!F26)/2)),"",'Data '!F58/(('Data '!E26+'Data '!F26)/2)) -> 0.64167834 | F24: =IF(ISERROR('Data '!G58/(('Data '!F26+'Data '!G26)/2)),"",'Data '!G58/(('Data '!F26+'Data '!G26)/2)) -> 0.57055043
A25: = Return on Assets | B25: =IF(ISERROR(('Data '!C79+((1-'Data '!C135)*-'Data '!C71)-'Data '!C137)/(('Data '!B26+'Data '!C26)/2)),"",('Data '!C79+((1-'Data '!C135)*-'Data '!C71)-'Data '!C137)/(('Data '!B26+'Data '!C26)/2)) -> 0.0088604897 | C25: =IF(ISERROR(('Data '!D79+((1-'Data '!D135)*-'Data '!D71)-'Data '!D137)/(('Data '!C26+'Data '!D26)/2)),"",('Data '!D79+((1-'Data '!D135)*-'Data '!D71)-'Data '!D137)/(('Data '!C26+'Data '!D26)/2)) -> 0.088463138 | D25: =IF(ISERROR(('Data '!E79+((1-'Data '!E135)*-'Data '!E71)-'Data '!E137)/(('Data '!D26+'Data '!E26)/2)),"",('Data '!E79+((1-'Data '!E135)*-'Data '!E71)-'Data '!E137)/(('Data '!D26+'Data '!E26)/2)) -> 0.090825969 | E25: =IF(ISERROR(('Data '!F79+((1-'Data '!F135)*-'Data '!F71)-'Data '!F137)/(('Data '!E26+'Data '!F26)/2)),"",('Data '!F79+((1-'Data '!F135)*-'Data '!F71)-'Data '!F137)/(('Data '!E26+'Data '!F26)/2)) -> 0.085669625 | F25: =IF(ISERROR(('Data '!G79+((1-'Data '!G135)*-'Data '!G71)-'Data '!G137)/(('Data '!F26+'Data '!G26)/2)),"",('Data '!G79+((1-'Data '!G135)*-'Data '!G71)-'Data '!G137)/(('Data '!F26+'Data '!G26)/2)) -> 0.017956007
A27: RETURN ON COMMON EQUITY (based on reported amounts):
A28: Profit Margin for ROCE | B28: =IF(ISERROR(('Data '!C81-'Data '!C139)/'Data '!C58),"",('Data '!C81-'Data '!C139)/'Data '!C58) -> -0.084071739 | C28: =IF(ISERROR(('Data '!D81-'Data '!D139)/'Data '!D58),"",('Data '!D81-'Data '!D139)/'Data '!D58) -> 0.073646435 | D28: =IF(ISERROR(('Data '!E81-'Data '!E139)/'Data '!E58),"",('Data '!E81-'Data '!E139)/'Data '!E58) -> 0.05560677 | E28: =IF(ISERROR(('Data '!F81-'Data '!F139)/'Data '!F58),"",('Data '!F81-'Data '!F139)/'Data '!F58) -> 0.022537969 | F28: =IF(ISERROR(('Data '!G81-'Data '!G139)/'Data '!G58),"",('Data '!G81-'Data '!G139)/'Data '!G58) -> -0.065777804
A29: x Asset Turnover | B29: =IF(ISERROR('Data '!C58/(('Data '!B26+'Data '!C26)/2)),"",'Data '!C58/(('Data '!B26+'Data '!C26)/2)) -> 0.49678062 | C29: =IF(ISERROR('Data '!D58/(('Data '!C26+'Data '!D26)/2)),"",'Data '!D58/(('Data '!C26+'Data '!D26)/2)) -> 0.63741066 | D29: =IF(ISERROR('Data '!E58/(('Data '!D26+'Data '!E26)/2)),"",'Data '!E58/(('Data '!D26+'Data '!E26)/2)) -> 0.70142169 | E29: =IF(ISERROR('Data '!F58/(('Data '!E26+'Data '!F26)/2)),"",'Data '!F58/(('Data '!E26+'Data '!F26)/2)) -> 0.64167834 | F29: =IF(ISERROR('Data '!G58/(('Data '!F26+'Data '!G26)/2)),"",'Data '!G58/(('Data '!F26+'Data '!G26)/2)) -> 0.57055043
A30: x Capital Structure Leverage | B30: =IF(ISERROR((('Data '!B26+'Data '!C26)/2)/(('Data '!B50+'Data '!C50)/2)),"",(('Data '!B26+'Data '!C26)/2)/(('Data '!B50+'Data '!C50)/2)) -> 2.530172 | C30: =IF(ISERROR((('Data '!C26+'Data '!D26)/2)/(('Data '!C50+'Data '!D50)/2)),"",(('Data '!C26+'Data '!D26)/2)/(('Data '!C50+'Data '!D50)/2)) -> 2.4438763 | D30: =IF(ISERROR((('Data '!D26+'Data '!E26)/2)/(('Data '!D50+'Data '!E50)/2)),"",(('Data '!D26+'Data '!E26)/2)/(('Data '!D50+'Data '!E50)/2)) -> 2.3542582 | E30: =IF(ISERROR((('Data '!E26+'Data '!F26)/2)/(('Data '!E50+'Data '!F50)/2)),"",(('Data '!E26+'Data '!F26)/2)/(('Data '!E50+'Data '!F50)/2)) -> 2.4401595 | F30: =IF(ISERROR((('Data '!F26+'Data '!G26)/2)/(('Data '!F50+'Data '!G50)/2)),"",(('Data '!F26+'Data '!G26)/2)/(('Data '!F50+'Data '!G50)/2)) -> 2.6926351
A31: = Return on Common Equity | B31: =IF(ISERROR(('Data '!C81-'Data '!C139)/(('Data '!B50+'Data '!C50)/2)),"",('Data '!C81-'Data '!C139)/(('Data '!B50+'Data '!C50)/2)) -> -0.10567316 | C31: =IF(ISERROR(('Data '!D81-'Data '!D139)/(('Data '!C50+'Data '!D50)/2)),"",('Data '!D81-'Data '!D139)/(('Data '!C50+'Data '!D50)/2)) -> 0.11472294 | D31: =IF(ISERROR(('Data '!E81-'Data '!E139)/(('Data '!D50+'Data '!E50)/2)),"",('Data '!E81-'Data '!E139)/(('Data '!D50+'Data '!E50)/2)) -> 0.091825004 | E31: =IF(ISERROR(('Data '!F81-'Data '!F139)/(('Data '!E50+'Data '!F50)/2)),"",('Data '!F81-'Data '!F139)/(('Data '!E50+'Data '!F50)/2)) -> 0.035289896 | F31: =IF(ISERROR(('Data '!G81-'Data '!G139)/(('Data '!F50+'Data '!G50)/2)),"",('Data '!G81-'Data '!G139)/(('Data '!F50+'Data '!G50)/2)) -> -0.1010534
A33: RETURN ON COMMON EQUITY (excluding the effects of nonrecurring items):
A34: Profit Margin for ROCE | B34: =IF(ISERROR(('Data '!C81-'Data '!C139-'Data '!C137)/'Data '!C58),"",('Data '!C81-'Data '!C139-'Data '!C137)/'Data '!C58) -> -0.057425709 | C34: =IF(ISERROR(('Data '!D81-'Data '!D139-'Data '!D137)/'Data '!D58),"",('Data '!D81-'Data '!D139-'Data '!D137)/'Data '!D58) -> 0.10583456 | D34: =IF(ISERROR(('Data '!E81-'Data '!E139-'Data '!E137)/'Data '!E58),"",('Data '!E81-'Data '!E139-'Data '!E137)/'Data '!E58) -> 0.083220622 | E34: =IF(ISERROR(('Data '!F81-'Data '!F139-'Data '!F137)/'Data '!F58),"",('Data '!F81-'Data '!F139-'Data '!F137)/'Data '!F58) -> 0.085949989 | F34: =IF(ISERROR(('Data '!G81-'Data '!G139-'Data '!G137)/'Data '!G58),"",('Data '!G81-'Data '!G139-'Data '!G137)/'Data '!G58) -> -0.017958315
A35: x Asset Turnover | B35: =IF(ISERROR('Data '!C58/(('Data '!B26+'Data '!C26)/2)),"",'Data '!C58/(('Data '!B26+'Data '!C26)/2)) -> 0.49678062 | C35: =IF(ISERROR('Data '!D58/(('Data '!C26+'Data '!D26)/2)),"",'Data '!D58/(('Data '!C26+'Data '!D26)/2)) -> 0.63741066 | D35: =IF(ISERROR('Data '!E58/(('Data '!D26+'Data '!E26)/2)),"",'Data '!E58/(('Data '!D26+'Data '!E26)/2)) -> 0.70142169 | E35: =IF(ISERROR('Data '!F58/(('Data '!E26+'Data '!F26)/2)),"",'Data '!F58/(('Data '!E26+'Data '!F26)/2)) -> 0.64167834 | F35: =IF(ISERROR('Data '!G58/(('Data '!F26+'Data '!G26)/2)),"",'Data '!G58/(('Data '!F26+'Data '!G26)/2)) -> 0.57055043
A36: x Capital Structure Leverage | B36: =IF(ISERROR((('Data '!B26+'Data '!C26)/2)/(('Data '!B50+'Data '!C50)/2)),"",(('Data '!B26+'Data '!C26)/2)/(('Data '!B50+'Data '!C50)/2)) -> 2.530172 | C36: =IF(ISERROR((('Data '!C26+'Data '!D26)/2)/(('Data '!C50+'Data '!D50)/2)),"",(('Data '!C26+'Data '!D26)/2)/(('Data '!C50+'Data '!D50)/2)) -> 2.4438763 | D36: =IF(ISERROR((('Data '!D26+'Data '!E26)/2)/(('Data '!D50+'Data '!E50)/2)),"",(('Data '!D26+'Data '!E26)/2)/(('Data '!D50+'Data '!E50)/2)) -> 2.3542582 | E36: =IF(ISERROR((('Data '!E26+'Data '!F26)/2)/(('Data '!E50+'Data '!F50)/2)),"",(('Data '!E26+'Data '!F26)/2)/(('Data '!E50+'Data '!F50)/2)) -> 2.4401595 | F36: =IF(ISERROR((('Data '!F26+'Data '!G26)/2)/(('Data '!F50+'Data '!G50)/2)),"",(('Data '!F26+'Data '!G26)/2)/(('Data '!F50+'Data '!G50)/2)) -> 2.6926351
A37: = Return on Common Equity | B37: =IF(ISERROR(('Data '!C81-'Data '!C139-'Data '!C137)/(('Data '!B50+'Data '!C50)/2)),"",('Data '!C81-'Data '!C139-'Data '!C137)/(('Data '!B50+'Data '!C50)/2)) -> -0.072180694 | C37: =IF(ISERROR(('Data '!D81-'Data '!D139-'Data '!D137)/(('Data '!C50+'Data '!D50)/2)),"",('Data '!D81-'Data '!D139-'Data '!D137)/(('Data '!C50+'Data '!D50)/2)) -> 0.16486408 | D37: =IF(ISERROR(('Data '!E81-'Data '!E139-'Data '!E137)/(('Data '!D50+'Data '!E50)/2)),"",('Data '!E81-'Data '!E139-'Data '!E137)/(('Data '!D50+'Data '!E50)/2)) -> 0.13742452 | E37: =IF(ISERROR(('Data '!F81-'Data '!F139-'Data '!F137)/(('Data '!E50+'Data '!F50)/2)),"",('Data '!F81-'Data '!F139-'Data '!F137)/(('Data '!E50+'Data '!F50)/2)) -> 0.13458028 | F37: =IF(ISERROR(('Data '!G81-'Data '!G139-'Data '!G137)/(('Data '!F50+'Data '!G50)/2)),"",('Data '!G81-'Data '!G139-'Data '!G137)/(('Data '!F50+'Data '!G50)/2)) -> -0.027589075
A39: OPERATING PERFORMANCE:
A40: Gross Profit / Revenues | B40: =IF(ISERROR('Data '!C60/'Data '!C58),"",'Data '!C60/'Data '!C58) -> 0.61752081 | C40: =IF(ISERROR('Data '!D60/'Data '!D58),"",'Data '!D60/'Data '!D58) -> 0.6877413 | D40: =IF(ISERROR('Data '!E60/'Data '!E58),"",'Data '!E60/'Data '!E58) -> 0.71985081 | E40: =IF(ISERROR('Data '!F60/'Data '!F58),"",'Data '!F60/'Data '!F58) -> 0.72598206 | F40: =IF(ISERROR('Data '!G60/'Data '!G58),"",'Data '!G60/'Data '!G58) -> 0.71491036
A41: Operating Profit / Revenues | B41: =IF(ISERROR('Data '!C69/'Data '!C58),"",'Data '!C69/'Data '!C58) -> -0.067197336 | C41: =IF(ISERROR('Data '!D69/'Data '!D58),"",'Data '!D69/'Data '!D58) -> 0.12635621 | D41: =IF(ISERROR('Data '!E69/'Data '!E58),"",'Data '!E69/'Data '!E58) -> 0.10220257 | E41: =IF(ISERROR('Data '!F69/'Data '!F58),"",'Data '!F69/'Data '!F58) -> 0.062288166 | F41: =IF(ISERROR('Data '!G69/'Data '!G58),"",'Data '!G69/'Data '!G58) -> -0.047339113
A42: Net Income / Revenues | B42: =IF(ISERROR('Data '!C81/'Data '!C58),"",'Data '!C81/'Data '!C58) -> -0.084071739 | C42: =IF(ISERROR('Data '!D81/'Data '!D58),"",'Data '!D81/'Data '!D58) -> 0.073646435 | D42: =IF(ISERROR('Data '!E81/'Data '!E58),"",'Data '!E81/'Data '!E58) -> 0.05560677 | E42: =IF(ISERROR('Data '!F81/'Data '!F58),"",'Data '!F81/'Data '!F58) -> 0.022537969 | F42: =IF(ISERROR('Data '!G81/'Data '!G58),"",'Data '!G81/'Data '!G58) -> -0.065777804
A43: Comprehensive Income / Revenues | B43: =IF(ISERROR('Data '!C85/'Data '!C58),"",'Data '!C85/'Data '!C58) -> -0.085045724 | C43: =IF(ISERROR('Data '!D85/'Data '!D58),"",'Data '!D85/'Data '!D58) -> 0.078324468 | D43: =IF(ISERROR('Data '!E85/'Data '!E58),"",'Data '!E85/'Data '!E58) -> 0.066684348 | E43: =IF(ISERROR('Data '!F85/'Data '!F58),"",'Data '!F85/'Data '!F58) -> 0.023983132 | F43: =IF(ISERROR('Data '!G85/'Data '!G58),"",'Data '!G85/'Data '!G58) -> -0.085117853
A45: PERSISTENT OPERATING PERFORMANCE (excluding the effects of nonrecurring items):
A46: Persistent Operating Profit / Revenues | B46: =IF(ISERROR(('Data '!C69-'Data '!C68)/'Data '!C58),"",('Data '!C69-'Data '!C68)/'Data '!C58) -> -0.092700025 | C46: =IF(ISERROR(('Data '!D69-'Data '!D68)/'Data '!D58),"",('Data '!D69-'Data '!D68)/'Data '!D58) -> 0.10285596 | D46: =IF(ISERROR(('Data '!E69-'Data '!E68)/'Data '!E58),"",('Data '!E69-'Data '!E68)/'Data '!E58) -> 0.063611992 | E46: =IF(ISERROR(('Data '!F69-'Data '!F68)/'Data '!F58),"",('Data '!F69-'Data '!F68)/'Data '!F58) -> 0.044227521 | F46: =IF(ISERROR(('Data '!G69-'Data '!G68)/'Data '!G58),"",('Data '!G69-'Data '!G68)/'Data '!G58) -> -0.070529975
A47: Persistent Net Income / Revenues | B47: =IF(ISERROR(('Data '!C81-'Data '!C137)/'Data '!C58),"",('Data '!C81-'Data '!C137)/'Data '!C58) -> -0.057425709 | C47: =IF(ISERROR(('Data '!D81-'Data '!D137)/'Data '!D58),"",('Data '!D81-'Data '!D137)/'Data '!D58) -> 0.10583456 | D47: =IF(ISERROR(('Data '!E81-'Data '!E137)/'Data '!E58),"",('Data '!E81-'Data '!E137)/'Data '!E58) -> 0.083220622 | E47: =IF(ISERROR(('Data '!F81-'Data '!F137)/'Data '!F58),"",('Data '!F81-'Data '!F137)/'Data '!F58) -> 0.085949989 | F47: =IF(ISERROR(('Data '!G81-'Data '!G137)/'Data '!G58),"",('Data '!G81-'Data '!G137)/'Data '!G58) -> -0.017958315
A49: GROWTH RATES:
A50: Revenue Growth | B50: =IF(ISERROR('Data '!C58/'Data '!B58-1),"",'Data '!C58/'Data '!B58-1) -> -0.33503889 | C50: =IF(ISERROR('Data '!D58/'Data '!C58-1),"",'Data '!D58/'Data '!C58-1) -> 0.23988753 | D50: =IF(ISERROR('Data '!E58/'Data '!D58-1),"",'Data '!E58/'Data '!D58-1) -> 0.10240947 | E50: =IF(ISERROR('Data '!F58/'Data '!E58-1),"",'Data '!F58/'Data '!E58-1) -> -0.076319212 | F50: =IF(ISERROR('Data '!G58/'Data '!F58-1),"",'Data '!G58/'Data '!F58-1) -> -0.10478945
A51: Net Income Growth | B51: =IF(ISERROR('Data '!C81/'Data '!B81-1),"",'Data '!C81/'Data '!B81-1) -> -1.880446 | C51: =IF(ISERROR('Data '!D81/'Data '!C81-1),"",'Data '!D81/'Data '!C81-1) -> -2.0861355 | D51: =IF(ISERROR('Data '!E81/'Data '!D81-1),"",'Data '!E81/'Data '!D81-1) -> -0.16762529 | E51: =IF(ISERROR('Data '!F81/'Data '!E81-1),"",'Data '!F81/'Data '!E81-1) -> -0.62562312 | F51: =IF(ISERROR('Data '!G81/'Data '!F81-1),"",'Data '!G81/'Data '!F81-1) -> -3.6127015
A52: Persistent Net Income Growth | B52: =IF(ISERROR((('Data '!C81-'Data '!C137)/('Data '!B81-'Data '!B137))-1),"",(('Data '!C81-'Data '!C137)/('Data '!B81-'Data '!B137))-1) -> -1.3925696 | C52: =IF(ISERROR((('Data '!D81-'Data '!D137)/('Data '!C81-'Data '!C137))-1),"",(('Data '!D81-'Data '!D137)/('Data '!C81-'Data '!C137))-1) -> -3.2850907 | D52: =IF(ISERROR((('Data '!E81-'Data '!E137)/('Data '!D81-'Data '!D137))-1),"",(('Data '!E81-'Data '!E137)/('Data '!D81-'Data '!D137))-1) -> -0.13314516 | E52: =IF(ISERROR((('Data '!F81-'Data '!F137)/('Data '!E81-'Data '!E137))-1),"",(('Data '!F81-'Data '!F137)/('Data '!E81-'Data '!E137))-1) -> -0.046025466 | F52: =IF(ISERROR((('Data '!G81-'Data '!G137)/('Data '!F81-'Data '!F137))-1),"",(('Data '!G81-'Data '!G137)/('Data '!F81-'Data '!F137))-1) -> -1.1870445
A54: OPERATING CONTROL:
...

Sheet Forecasts 
A2: FSAP OUTPUT: | B2: FINANCIAL STATEMENT FORECASTS
A3: ='Data '!A2 -> Analyst Name: | B3: ='Data '!B2 -> ARYAN Shrenick kothari
A4: ='Data '!A3 -> Company Name: | B4: ='Data '!B3 -> Salvatore Ferragamo Group
B6: Row Format: | E6: Row Format:
B7: Actual Amounts | E7: Forecast Amounts | J7: Year +6 and beyond:
B8: Common Size Percentage | E8: Forecast assumption | I8: Long-Run Growth Rate: | J8: ='Valuation '!$F$23 -> 0.03
B9: Rate of Change Percentage | E9: Forecast assumption explanation | I9: Long-Run Growth Factor: | J9: =1+$J$8 -> 1.03
B11: Actuals | E11: Forecasts
A12: Year | B12: ='Data '!E4 -> 2022 | C12: ='Data '!F4 -> 2023 | D12: ='Data '!G4 -> 2024 | E12: Year +1 | F12: Year +2 | G12: Year +3 | H12: Year +4 | I12: Year +5 | J12: Year +6
A13: INCOME STATEMENT
A14: ='Data '!A58 -> Revenues | B14: ='Data '!E58 -> 1251808 | C14: ='Data '!F58 -> 1156271 | D14: ='Data '!G58 -> 1035106 | E14: ='Forecast Development '!E16 -> 1046253.4 | F14: ='Forecast Development '!F16 -> 1083489.9 | G14: ='Forecast Development '!G16 -> 1131787.8 | H14: ='Forecast Development '!H16 -> 1184145.7 | I14: ='Forecast Development '!I16 -> 1233098.5 | J14: =I14*$J$9 -> 1270091.4
A15: common size | B15: =B14/B$14 -> 1 | C15: =C14/C$14 -> 1 | D15: =D14/D$14 -> 1 | E15: =E14/D14-1 -> 0.01076937 | F15: =F14/E14-1 -> 0.035590249 | G15: =G14/F14-1 -> 0.04457624 | H15: =H14/G14-1 -> 0.046261272 | I15: =I14/H14-1 -> 0.041340155
A16: rate of change | C16: =IF(ISERROR(C14/B14-1),"",C14/B14-1) -> -0.076319212 | D16: =IF(ISERROR(D14/C14-1),"",D14/C14-1) -> -0.10478945 | E16: See Forecast Development worksheet for details of revenues forecasts.
A17: ='Data '!A59 -> <Cost of goods sold> | B17: ='Data '!E59 -> -350693 | C17: ='Data '!F59 -> -316839 | D17: ='Data '!G59 -> -295098 | E17: =-'Forecast Development '!E116 -> -298182.23 | F17: =-'Forecast Development '!F116 -> -308794.61 | G17: =-'Forecast Development '!G116 -> -322559.51 | H17: =-'Forecast Development '!H116 -> -337481.53 | I17: =-'Forecast Development '!I116 -> -351433.06 | J17: =I17*$J$9 -> -361976.06
A18: common size | B18: =B17/B$14 -> -0.28014919 | C18: =C17/C$14 -> -0.27401794 | D18: =D17/D$14 -> -0.28508964 | E18: =E17/E14 -> -0.285 | F18: =F17/F14 -> -0.285 | G18: =G17/G14 -> -0.285 | H18: =H17/H14 -> -0.285 | I18: =I17/I14 -> -0.285
A19: rate of change | B19: =AVERAGE(B18:D18) -> -0.27975226 | C19: =IF(ISERROR(C17/B17-1),"",C17/B17-1) -> -0.096534576 | D19: =IF(ISERROR(D17/C17-1),"",D17/C17-1) -> -0.068618447 | E19: See Forecast Development worksheet.
A20: ='Data '!A60 -> Gross Profit | B20: =B14+B17 -> 901115 | C20: =C14+C17 -> 839432 | D20: =D14+D17 -> 740008 | E20: =E14+E17 -> 748071.21 | F20: =F14+F17 -> 774695.25 | G20: =G14+G17 -> 809228.25 | H20: =H14+H17 -> 846664.18 | I20: =I14+I17 -> 881665.41 | J20: =J14+J17 -> 908115.37
A21: common size | B21: =B20/B$14 -> 0.71985081 | C21: =C20/C$14 -> 0.72598206 | D21: =D20/D$14 -> 0.71491036 | E21: =E20/E$14 -> 0.715 | F21: =F20/F$14 -> 0.715 | G21: =G20/G$14 -> 0.715 | H21: =H20/H$14 -> 0.715 | I21: =I20/I$14 -> 0.715 | J21: =J20/J$14 -> 0.715
A22: rate of change | C22: =IF(ISERROR(C20/B20-1),"",C20/B20-1) -> -0.068451862 | D22: =IF(ISERROR(D20/C20-1),"",D20/C20-1) -> -0.11844199 | E22: =IF(ISERROR(E20/D20-1),"",E20/D20-1) -> 0.010896111 | F22: =IF(ISERROR(F20/E20-1),"",F20/E20-1) -> 0.035590249 | G22: =IF(ISERROR(G20/F20-1),"",G20/F20-1) -> 0.04457624 | H22: =IF(ISERROR(H20/G20-1),"",H20/G20-1) -> 0.046261272 | I22: =IF(ISERROR(I20/H20-1),"",I20/H20-1) -> 0.041340155
A24: ='Data '!A61 -> <Operating Expenses (1)> | B24: ='Data '!E61 -> -311353 | C24: ='Data '!F61 -> -274860 | D24: ='Data '!G61 -> -232300 | E24: =E14*E25 -> -240638.29 | F24: =F14*F25 -> -249202.67 | G24: =G14*G25 -> -260311.19 | H24: =H14*H25 -> -272353.51 | I24: =I14*I25 -> -283612.65 | J24: =I24*$J$9 -> -292121.03
A25: common size | B25: =B24/B$14 -> -0.24872265 | C25: =C24/C$14 -> -0.23771244 | D25: =D24/D$14 -> -0.22442146 | E25: -0.23 | F25: -0.23 | G25: -0.23 | H25: -0.23 | I25: -0.23
A26: rate of change | B26: =AVERAGE((B25:D25)) -> -0.23695218 | C26: =IF(ISERROR(C24/B24-1),"",C24/B24-1) -> -0.1172078 | D26: =IF(ISERROR(D24/C24-1),"",D24/C24-1) -> -0.15484247 | E26: SG&A rationalization under brand relaunch: assume -0.7pp improvement per year, stabilizing at 23.0% of revenues by Year +1. FY2022–2024 avg ~23.7%.
A27: ='Data '!A62 -> <Operating Expenses (2)> | B27: ='Data '!E62 -> -168819 | C27: ='Data '!F62 -> -137142 | D27: ='Data '!G62 -> -157093 | E27: =E14*E28 -> -124504.16 | F27: =F14*F28 -> -128935.29 | G27: =G14*G28 -> -134682.74 | H27: =H14*H28 -> -140913.34 | I27: =I14*I28 -> -146738.72 | J27: =I27*$J$9 -> -151140.88
A28: common size | B28: =B27/B$14 -> -0.13486014 | C28: =C27/C$14 -> -0.11860714 | D28: =D27/D$14 -> -0.15176513 | E28: -0.119 | F28: -0.119 | G28: -0.119 | H28: -0.119 | I28: -0.119
A29: rate of change | B29: =AVERAGE((B28:D28)) -> -0.13507747 | C29: =IF(ISERROR(C27/B27-1),"",C27/B27-1) -> -0.18763883 | D29: =IF(ISERROR(D27/C27-1),"",D27/C27-1) -> 0.14547695 | E29: Distribution/retail OpEx: held at 11.9% of revenues, reflecting DTC channel cost structure. FY2022–2024 avg ~13.4%, but 2024A elevated by transformation costs.
A30: ='Data '!A63 -> <Depreciation and Amortization> | B30: =-'Data '!E91 -> -170962 | C30: =-'Data '!F91 -> -179789 | D30: =-'Data '!G91 -> -264219 | E30: =-('Forecast Development '!E80*0.95+'Forecast Development '!E85) -> -271999.81 | F30: =-('Forecast Development '!F80*0.95+'Forecast Development '!F85) -> -271347.09 | G30: =-('Forecast Development '!G80*0.95+'Forecast Development '!G85) -> -270805.08 | H30: =-('Forecast Development '!H80*0.95+'Forecast Development '!H85) -> -270372.03 | I30: =-('Forecast Development '!I80*0.95+'Forecast Development '!I85) -> -270066.03 | J30: =I30*$J$9 -> -278168.01
A31: common size | B31: =B30/B$14 -> -0.13657206 | C31: =C30/C$14 -> -0.15549037 | D31: =D30/D$14 -> -0.25525792
A32: rate of change | B32: =AVERAGE((B31:D31)) -> -0.18244011 | C32: =IF(ISERROR(C30/B30-1),"",C30/B30-1) -> 0.051631357 | D32: =IF(ISERROR(D30/C30-1),"",D30/C30-1) -> 0.46960604 | E32: Amounts from depreciation schedule, Forecast Development worksheet.
A33: ='Data '!A64 -> <Selling, General and Administrative Expenses> | B33: ='Data '!E64 -> -49263 | C33: ='Data '!F64 -> -53086 | D33: ='Data '!G64 -> -47038 | E33: =E14*E34 -> -46035.151 | F33: =F14*F34 -> -47673.554 | G33: =G14*G34 -> -49798.662 | H33: =H14*H34 -> -52102.411 | I33: =I14*I34 -> -54256.333 | J33: =I33*$J$9 -> -55884.023
A34: common size | B34: =B33/B$14 -> -0.039353479 | C34: =C33/C$14 -> -0.045911382 | D34: =D33/D$14 -> -0.045442689 | E34: -0.044 | F34: -0.044 | G34: -0.044 | H34: -0.044 | I34: -0.044
A35: rate of change | B35: =AVERAGE(B34:D34) -> -0.043569183 | C35: =IF(ISERROR(C33/B33-1),"",C33/B33-1) -> 0.077603881 | D35: =IF(ISERROR(D33/C33-1),"",D33/C33-1) -> -0.11392834 | E35: SG&A expense: 4.4% of revenues, slightly below FY2022–2024 avg of ~4.4%. Held flat as marketing investment maintains brand relaunch spend.
A36: ='Data '!A65 -> Other operating expenses (1) | B36: ='Data '!E65 -> -92064 | C36: ='Data '!F65 -> -113695 | D36: ='Data '!G65 -> -86661 | E36: =E14*E37 -> -83700.275 | F36: =F14*F37 -> -86679.189 | G36: =G14*G37 -> -90543.021 | H36: =H14*H37 -> -94731.656 | I36: =I14*I37 -> -98647.878 | J36: =I36*$J$9 -> -101607.31
A37: common size | B37: =B36/B$14 -> -0.073544825 | C37: =C36/C$14 -> -0.098329025 | D37: =D36/D$14 -> -0.08372186 | E37: -0.08 | F37: -0.08 | G37: -0.08 | H37: -0.08 | I37: -0.08
A38: rate of change | B38: =AVERAGE(B37:D37) -> -0.08519857 | C38: =IF(ISERROR(C36/B36-1),"",C36/B36-1) -> 0.23495612 | D38: =IF(ISERROR(D36/C36-1),"",D36/C36-1) -> -0.23777651 | E38: Other operating expenses: 8.0% of revenues, below FY2023 peak of 9.8%, in line with FY2022 (7.4%). Reflects normalization post-restructuring charge cycle.
A39: ='Data '!A66 -> Other operating expenses (2) | B39: ='Data '!E66 -> -29024 | C39: ='Data '!F66 -> -29721 | D39: ='Data '!G66 -> -25703 | E39: =E$14*E40 -> -25110.083 | F39: =F$14*F40 -> -26003.757 | G39: =G$14*G40 -> -27162.906 | H39: =H$14*H40 -> -28419.497 | I39: =I$14*I40 -> -29594.363 | J39: =I39*$J$9 -> -30482.194
A40: common size | B40: =B39/B$14 -> -0.023185664 | C40: =C39/C$14 -> -0.025704182 | D40: =D39/D$14 -> -0.024831273 | E40: =B41 -> -0.024 | F40: =E40 -> -0.024 | G40: =F40 -> -0.024 | H40: =G40 -> -0.024 | I40: =H40 -> -0.024
A41: rate of change | B41: -0.024 | C41: =IF(ISERROR(C39/B39-1),"",C39/B39-1) -> 0.024014609 | D41: =IF(ISERROR(D39/C39-1),"",D39/C39-1) -> -0.13519061 | E41: Other operating expenses (2): 2.4% of revenues, consistent with FY2022–2024 avg. Represents misc. admin and insurance-type expenses.
A42: ='Data '!A67 -> Income from equity investees | B42: ='Data '!E67 -> 0 | C42: ='Data '!F67 -> 0 | D42: ='Data '!G67 -> 0 | E42: =E$14*E43 -> 0 | F42: =F$14*F43 -> 0 | G42: =G$14*G43 -> 0 | H42: =H$14*H43 -> 0 | I42: =I$14*I43 -> 0 | J42: =I42*$J$9 -> 0
A43: common size | B43: =B42/B$14 -> 0 | C43: =C42/C$14 -> 0 | D43: =D42/D$14 -> 0 | E43: 0 | F43: =E43 -> 0 | G43: =F43 -> 0 | H43: =G43 -> 0 | I43: =H43 -> 0
A44: rate of change | C44: =IF(ISERROR(C42/B42-1),"",C42/B42-1) | D44: =IF(ISERROR(D42/C42-1),"",D42/C42-1) | E44: Income from equity investees: zero — no disclosed equity method investments. Consistent with FY2022–2024 reported nil.
...

Sheet Valuation 
A2: DATA CHECKS - Estimated Value per Share
A3: Dividend Based Valuation | F3: =E77 -> -2.4621218
A4: Free Cash Flow Valuation | F4: =E107 -> -2.4622259
A5: Residual Income Valuation | F5: =E164 -> -2.459166
A6: Residual Income Market-to-Book Valuation | F6: =E225 -> -2.459166
A7: Free Cash Flow for All Debt and Equity Valuation | F7: =E261 -> -4.2351883
A12: FSAP OUTPUT: | C12: VALUATION MODELS
A13: ='Data '!$A$2 -> Analyst Name: | C13: ='Data '!$B$2 -> ARYAN Shrenick kothari
A14: ='Data '!$A$3 -> Company Name: | C14: ='Data '!$B$3 -> Salvatore Ferragamo Group
A16: VALUATION PARAMETER ASSUMPTIONS
A18: Current share price | F18: =G18 -> 6.82 | G18: 6.82 | H18: yahoo finance as of 28th nov 2025
A19: Number of shares outstanding | F19: ='Data '!$G$140 -> 168790
A20: Current market value | F20: =F18*F19 -> 1151147.8
A22: Long-run growth assumption used in forecasts | F22: ='Forecasts '!$J$8 -> 0.03
A23: Long-run growth assumption used in valuation. | F23: 0.03
A24: (Both long-run growth assumptions should be the same.)
A26: COST OF EQUITY CAPITAL:
A27: Equity risk factor (market beta) | F27: =BETA!H262 -> 0.82449761
A28: Risk free rate | F28: 0.0315
A29: Market risk premium | F29: 0.05
A30: Required rate of return on common equity: | F30: =F28+F27*F29 -> 0.072724881
A32: COST OF DEBT CAPITAL
A33: Debt capital | F33: =('Forecasts '!D170+'Forecasts '!D173+'Forecasts '!D191) -> 567067
A34: Cost of debt capital, before tax | F34: =-'Forecasts '!E56 -> 0.06
A35: Effective tax rate | F35: 0.155
A36: After-tax cost of debt capital | F36: =F34*(1- F35) -> 0.0507
A38: COST OF PREFERRED STOCK
A39: Preferred stock capital | F39: 0
A40: Preferred dividends | F40: 0
A41: Implied yield | F41: 0
